Workbook

Sheet Guia_avance
A1: Guía de avance de la matriz v5 – se completa en orden según el itinerario
A3: Hoja | B3: Actividad del itinerario | C3: Qué se registra | D3: Estado
A4: Protocolo | B4: 1. Inducción | C4: Resumen del protocolo v3 (objetivo, RQ, criterios, calidad). | D4: Completada (validada el 01/10/2026)
A5: Cadenas_de_busqueda | B5: 3. Búsqueda y organización | C5: Las 16 cadenas ejecutadas, con fecha y registros exportados. | D5: Completada (validada el 01/10/2026)
A6: Base_consolidada | B6: 3. Búsqueda y organización | C6: Todos los registros exportados, con ID y categoría. | D6: Completada (validada el 01/10/2026)
A7: Duplicados_y_exclusion | B7: 4. PRISMA | C7: Duplicados y estudios secundarios retirados antes del cribado. | D7: Completada (validada el 02/10/2026)
A8: Tamizaje_Tit_Abs_Keys | B8: 4. PRISMA | C8: Cribado por título, resumen y palabras clave. | D8: Completada (validada el 02/10/2026)
A9: Texto_completo | B9: 4. PRISMA | C9: Elegibilidad a texto completo y motivos de exclusión. | D9: Completada (validada el 02/10/2026)
A10: Calidad_articulos | B10: 5. Calidad | C10: Q1–Q10 de los estudios elegibles. | D10: Completada (validada el 02/10/2026)
A11: Articulos_finales | B11: 6. Extracción y análisis | C11: Extracción de datos y decisión final (Incluir/Reserva). | D11: Completada (validada el 02/10/2026)
A12: Articulos_finales_ok | B12: 6. Extracción y análisis | C12: Tablas de síntesis. | D12: Completada (validada el 02/10/2026)
A13: Resumen_ejecutivo | B13: 6. Extracción y análisis | C13: Patrones, vacíos y recomendación. | D13: Completada (validada el 02/10/2026)
A14: PRISMA | B14: 7. Diagrama PRISMA | C14: Conteos del diagrama de flujo (automáticos) y comprobaciones; figura en 04_PRISMA/PRISMA_2020_diagrama_v2.png. | D14: Completada (validada el 02/10/2026)
... A17: Nota | B17: 8. Redacción de la SLR | C17: La Actividad 8 no tiene hoja en esta matriz: su entregable es SLR_SmartAgriculture/05_Redaccion_SLR/SLR_tallos_aguacate_v1.docx (tablas generadas desde esta matriz). | D17: Entregada el 02/10/2026 (pendiente de validación)

Sheet Protocolo
A1: PROTOCOLO DE LA REVISIÓN SISTEMÁTICA – resumen del Protocolo_SLR_SmartAgriculture_v3.docx (Actividad 1)
A2: Una sola revisión sistemática y un solo diagrama PRISMA, con dos categorías de estudios evaluadas con sus propios criterios. Solo se usan fuentes de Grupos v2.
A3: 1. Tema / Proyecto | B3: Smart Agriculture: aplicación móvil con IA para diagnosticar enfermedades y alteraciones visibles en el TALLO del aguacate.
A4: 2. Objetivo | B4: Analizar y sintetizar la literatura sobre las enfermedades del tallo del aguacate (agentes, síntomas visibles, métodos de detección) y sobre los sistemas de IA para el diagnóstico de enfermedades en cultivos (técnicas, datos, métricas, implementación e IPO), para fundamentar una aplicación móvil de diagnóstico en tallos.
A5: 3. Pregunta principal | B5: ¿Qué evidencia científica existe sobre las enfermedades y alteraciones del tallo del aguacate y sobre los sistemas basados en IA para el diagnóstico de enfermedades en cultivos, que permita fundamentar el desarrollo de una aplicación móvil para el diagnóstico en tallos de aguacate?
A6: RQ1 | B6: ¿Qué agentes causales y enfermedades afectan al tallo, las ramas y el tronco del aguacate, y en qué regiones se han reportado?
A7: RQ2 | B7: ¿Qué síntomas visibles producen estas enfermedades y qué métodos se utilizan para su detección y diagnóstico?
A8: RQ3 | B8: ¿Qué técnicas de IA y visión por computador, conjuntos de datos y métricas se emplean en los sistemas de diagnóstico de enfermedades en cultivos?
A9: RQ4 | B9: ¿Qué características de implementación (plataforma, inferencia, funcionamiento sin conexión) y de IPO presentan estos sistemas?
A10: RQ5 | B10: ¿Qué brechas y oportunidades se identifican para desarrollar una aplicación móvil de diagnóstico de enfermedades en tallos de aguacate?
A11: 4. Bases de datos | B11: Scopus, ScienceDirect y Springer Link. IEEE Xplore y Web of Science no se consultaron por falta de acceso institucional (limitación).
A12: 5. Grupos de cadenas | B12: Fitopatológicas (17–18/09/2026; 2003–2026) · Tecnológicas (25/09/2026; 2015–2026) · Complementarias C16–C18 en ScienceDirect (01/10/2026): recuperan revisiones que no entran a la síntesis y sirven de fuente para los antecedentes y el estado del arte.
A13: 6. Idioma | B13: Español o inglés.
A14: 7. Método | B14: Directrices de Kitchenham y Charters (como se citó en Martinelli et al., 2024) y declaración PRISMA (aplicada en Lin et al., 2026; Majdalawieh et al., 2025; Odounfa et al., 2024; Sajitha et al., 2024). Un revisor principal, con la tutora como segunda instancia.
A15: CATEGORÍA FITOPATOLÓGICA
A16: CI-F1 | B16: Trata sobre aguacate (Persea americana).
A17: CI-F2 | B17: Menciona uno de los grupos de patógenos considerados (Phytophthora, Lasiodiplodia, Botryosphaeriaceae, Colletotrichum, Fusarium, Nectria/Rugonectria).
A18: CI-F3 | B18: Aporta información sobre el tallo, ramas o tronco (síntomas, cancro, muerte descendente, pudrición, marchitez, detección).
A19: CI-F4 | B19: Es un estudio primario, en español o inglés, publicado entre 2003 y 2026.
A20: CE-F1 | B20: Se enfoca únicamente en raíz, hoja o fruto, sin relación con el tallo (incluye la pudrición peduncular o “stem-end rot” del fruto).
A21: CE-F2 | B21: Es revisión, survey, mapping o metaanálisis.
A22: CE-F3 | B22: No especifica la especie del patógeno ni el órgano afectado.
A23: CE-F4 / CE-F5 | B23: Duplicado; fuera del periodo o del idioma.
A24: Q1–Q10 fitopatológicos | B24: Q1 objetivo claro · Q2 patógeno identificado · Q3 síntomas en tallo descritos · Q4 aguacate · Q5 metodología replicable · Q6 evidencia (imágenes, mediciones, secuencias) · Q7 métodos de detección útiles para la app · Q8 contexto geográfico · Q9 resultados coherentes · Q10 fuente confiable y actual.
A25: CATEGORÍA TECNOLÓGICA
A26: CI-T1 | B26: Aborda la detección, clasificación o diagnóstico de enfermedades de plantas o cultivos.
A27: CI-T2 | B27: Usa IA, machine learning, deep learning o visión por computador.
A28: CI-T3 | B28: Se relaciona con una aplicación móvil, dispositivo o sistema de apoyo (o analiza su viabilidad).
A29: CI-T4 | B29: Es un estudio primario, en español o inglés, publicado entre 2015 y 2026.
A30: CE-T1 | B30: No usa IA ni métodos de aprendizaje automático.
A31: CE-T2 | B31: No aborda enfermedades de plantas (p. ej., madurez, calidad del fruto, estrés hídrico).
A32: CE-T3 / CE-T4 | B32: Revisión o estudio secundario; duplicado o fuera del periodo o idioma.
A33: Q1–Q10 tecnológicos | B33: Q1 objetivo claro · Q2 problema de detección definido · Q3 dataset especificado · Q4 modelo replicable · Q5 métricas con validación adecuada · Q6 comparación con otros modelos · Q7 implementación en app o dispositivo · Q8 IPO/UX/usabilidad · Q9 resultados coherentes y reproducibles · Q10 fuente confiable y actual.
A34: PUNTUACIÓN Y DECISIÓN
A35: Escala | B35: 0 = no cumple · 1 = parcial · 2 = cumple. Total 0–20 → Alta 16–20 · Media 11–15 · Baja ≤ 10.
A36: Decisión final | B36: Incluir si la calidad es Alta o Media y la alineación con el objetivo es Alta o Media; en otro caso, Reserva (se cita, pero no entra en la síntesis).
A37: Datos a extraer | B37: Fitopatológicos: patógeno, especie, órgano, síntomas en tallo, método de detección, país, aporte. Tecnológicos: modelo, dataset, métrica, plataforma e inferencia, IPO/usabilidad, país, aporte.

Sheet Cadenas_de_busqueda
A1: CADENAS DE BÚSQUEDA (registro para reproducibilidad)
A2: Se completa en la Actividad 3 del itinerario. Registro de las cadenas EXACTAS ejecutadas, con fecha y n.º de registros exportados (bitácora de búsqueda). IEEE Xplore y Web of Science no se consultaron por falta de acceso institucional.
A4: N.º | B4: Grupo | C4: Base de datos | D4: Cadena de búsqueda exacta | E4: Campos | F4: Filtros (años/idioma) | G4: Fecha de búsqueda | H4: N.º registros exportados | I4: Notas
A5: CADENAS FITOPATOLÓGICAS (17 y 18/09/2026)
A6: 1 | B6: Fitopatológica – todos los grupos de patógenos | C6: Scopus | D6: ("Persea americana" OR avocado) AND ("Phytophthora cinnamomi" OR "Lasiodiplodia theobromae" OR "Neofusicoccum parvum" OR Botryosphaeriaceae OR Colletotrichum OR Fusarium OR Nectria OR Rugonectria) AND (stem OR trunk OR canker OR dieback OR "stem-end rot" OR wilt OR disease OR symptom) | E6: Título-Resumen-Keywords | F6: 2003–2026; es/en | G6: 2026-09-17 | H6: 19 | I6: Export: scopus_export_Sep 17-2026_64f2de15. Cadena general, todos los grupos. Total de resultados (hits) no registrado (limitación declarada).
A7: 2 | B7: Fitopatológica – todos los grupos de patógenos | C7: Science Direct | D7: ("Persea americana" OR avocado) AND ("Phytophthora" OR Botryosphaeriaceae OR Colletotrichum OR Fusarium OR Nectria OR Rugonectria) | E7: Título-Resumen-Keywords | F7: 2003–2026; es/en | G7: 2026-09-18 | H7: 7 | I7: 7 registros (A0039–A0045), .ris en Grupos v2/Todos/Science Direct. Total de resultados (hits) no registrado (limitación declarada).
A8: 3 | B8: Fitopatológica – todos los grupos de patógenos | C8: Springer Link | D8: ("Persea americana" OR avocado) AND ("Phytophthora cinnamomi" OR "Lasiodiplodia theobromae" OR "Neofusicoccum parvum" OR Botryosphaeriaceae OR Colletotrichum OR Fusarium OR Nectria OR Rugonectria) AND (stem OR trunk OR canker OR dieback OR "stem-end rot" OR wilt OR disease OR symptom) | E8: Título-Resumen-Keywords | F8: 2003–2026; es/en | G8: 2026-09-17 | H8: 3 | I8: 3 registros (A0046–A0048), .ris en Grupos v2/Todos/springer. Total de resultados (hits) no registrado (limitación declarada).
A9: 4 | B9: Fitopatológica – 1. Phytophthora | C9: Scopus | D9: ("Persea americana" OR avocado) AND "Phytophthora cinnamomi" AND (root OR stem OR trunk OR wilt OR dieback) | E9: Título-Resumen-Keywords | F9: 2003–2026; es/en | G9: 2026-09-18 | H9: 7 | I9: Export: scopus_export_Sep 18-2026_162c1d26. Total de resultados (hits) no registrado (limitación declarada).
A10: 5 | B10: Fitopatológica – 2. Lasiodiplodia | C10: Scopus | D10: ("Persea americana" OR avocado) AND "Lasiodiplodia theobromae" AND (stem OR trunk OR canker OR "stem-end rot") | E10: Título-Resumen-Keywords | F10: 2003–2026; es/en | G10: 2026-09-18 | H10: 4 | I10: Export: scopus_export_Sep 18-2026_8f28b456. Total de resultados (hits) no registrado (limitación declarada).
A11: 6 | B11: Fitopatológica – 3. Botryosphaeriaceae | C11: Scopus | D11: ("Persea americana" OR avocado) AND ("Neofusicoccum parvum" OR Botryosphaeriaceae) AND (stem OR trunk OR canker OR dieback) | E11: Título-Resumen-Keywords | F11: 2003–2026; es/en | G11: 2026-09-18 | H11: 6 | I11: Export: scopus_export_Sep 18-2026_96199bb3. Total de resultados (hits) no registrado (limitación declarada).
A12: 7 | B12: Fitopatológica – 4. Colletotrichum | C12: Scopus | D12: ("Persea americana" OR avocado) AND ("Colletotrichum acutatum" OR "Colletotrichum gloeosporioides") AND (anthracnose OR stem OR canker) | E12: Título-Resumen-Keywords | F12: 2003–2026; es/en | G12: 2026-09-17 / 2026-09-18 | H12: 4 | I12: Dos exports: Sep 17-2026_2fb2f4b0 (1) + Sep 18-2026_82c23d75 (3). Total de resultados (hits) no registrado (limitación declarada).
A13: 8 | B13: Fitopatológica – 5. Fusarium | C13: Scopus | D13: ("Persea americana" OR avocado) AND ("Fusarium solani" OR "Fusarium oxysporum" OR "Fusarium equiseti") AND (wilt OR stem OR trunk OR rot) | E13: Título-Resumen-Keywords | F13: 2003–2026; es/en | G13: 2026-09-18 | H13: 2 | I13: Export: scopus_export_Sep 18-2026_4e658477. Total de resultados (hits) no registrado (limitación declarada).
A14: 9 | B14: Fitopatológica – 6. Nectria | C14: Scopus | D14: ("Persea americana" OR avocado) AND (Nectria OR "Rugonectria rugulosa") AND (canker OR trunk OR stem) | E14: Título-Resumen-Keywords | F14: 2003–2026; es/en | G14: 2026-09-18 | H14: 4 | I14: Export: scopus_export_Sep 18-2026_6573fc91. Total de resultados (hits) no registrado (limitación declarada).
A15: CADENAS TECNOLÓGICAS (25/09/2026)
A16: 12 | B16: Tecnológica – Aguacate+IA (stem) | C16: Scopus | D16: ( "Persea americana" OR avocado ) AND ( "deep learning" OR "machine learning" OR "computer vision" OR CNN OR "image classification" ) AND ( stem OR detection OR classification ) | E16: Título-Resumen-Keywords | F16: 2015–2026; es/en | G16: 2026-09-25 | H16: 13 | I16: Exportación conjunta de las cadenas 12–14: 13 registros; 1 duplicado dentro de Scopus (T0001, presente en dos exportaciones) → 12 únicos (T0001–T0012). Total de resultados (hits) no registrado (limitación declarada).
A17: 13 | B17: Tecnológica – Enfermedad+IA+HCI | C17: Scopus | D17: ( "plant disease" OR "crop disease" OR "leaf disease" ) AND ( "deep learning" OR "machine learning" OR "computer vision" OR "artificial intelligence" ) AND ( usability OR "user experience" OR UX OR "human-computer interaction" OR HCI OR "user interface" OR "user-centered design" ) | E17: Título-Resumen-Keywords | F17: 2015–2026; es/en | G17: 2026-09-25 | H17: 0 | I17: Sus registros se contabilizan en la cadena 12 (exportación conjunta). Total de resultados (hits) no registrado (limitación declarada).
A18: 14 | B18: Tecnológica – Aguacate+IA (disease/pest) | C18: Scopus | D18: (avocado OR "Persea americana") AND ("deep learning" OR "machine learning" OR "computer vision" OR CNN OR "image classification" OR "artificial intelligence") AND (disease OR detection OR classification OR pest) | E18: Título-Resumen-Keywords | F18: 2015–2026; es/en | G18: 2026-09-25 | H18: 0 | I18: Sus registros se contabilizan en la cadena 12 (exportación conjunta). Total de resultados (hits) no registrado (limitación declarada).
A19: 15 | B19: Tecnológica – Aguacate+IA+HCI | C19: Springer Link | D19: ("persea americana" OR avocado) AND ("deep learning" OR "machine learning" OR "computer vision") AND (usability OR "user experience" OR "human-computer interaction" OR "user interface") | E19: Título-Resumen-Keywords | F19: 2015–2026; es/en | G19: 2026-09-25 | H19: 1 | I19: 1 registro exportado (T0013); .ris en Grupos v2/Todos/springer. Total de resultados (hits) no registrado (limitación declarada).
A20: CADENAS COMPLEMENTARIAS EN SCIENCEDIRECT (01/10/2026) – revisiones para el estado del arte
A21: 16 | B21: Complementaria – Smart agriculture + IA | C21: Science Direct | D21: ("smart agriculture" OR "smart farming" OR "precision agriculture") AND ("deep learning" OR "computer vision") AND review | E21: Título-Resumen-Keywords | F21: No registrado (registros de 2024–2026, en inglés) | G21: 2026-10-01 | H21: 4 | I21: ScienceDirect_citations_1790890165413.ris: Odounfa 2024 (T0014), Yuan 2026 (T0015), Lin 2026 (T0016), Majdalawieh 2025 (T0017). Total de resultados (hits) no registrado (limitación declarada).
A22: 17 | B22: Complementaria – Detección de enfermedades en plantas con imágenes | C22: Science Direct | D22: ("plant disease" OR "crop disease") AND ("deep learning" OR CNN) AND (detection OR classification) | E22: Título-Resumen-Keywords | F22: No registrado (registros de 2024–2026, en inglés) | G22: 2026-10-01 | H22: 3 | I22: ScienceDirect_citations_1790890637540.ris: Saini 2026 (T0018), Sajitha 2024 (T0019) y Majdalawieh 2025, ya recuperado en la cadena 16 (1 duplicado dentro de ScienceDirect). Total de resultados (hits) no registrado (limitación declarada).
A23: 18 | B23: Complementaria – Apps móviles + HCI en agricultura | C23: Science Direct | D23: ("mobile application" OR smartphone) AND (agriculture OR farmer*) AND (usability OR "user-centered design" OR "user experience") | E23: Título-Resumen-Keywords | F23: No registrado (registro de 2024, en inglés) | G23: 2026-10-01 | H23: 1 | I23: ScienceDirect_citations_1790891064720.ris: Martinelli 2024 (T0020). Total de resultados (hits) no registrado (limitación declarada).
A25: RESUMEN DE LA BÚSQUEDA
B26: Registros exportados – Scopus | H26: =SUMIF($C$5:$C$23,"Scopus",$H$5:$H$23) -> 59
B27: Registros exportados – ScienceDirect | H27: =SUMIF($C$5:$C$23,"Science Direct",$H$5:$H$23) -> 15
B28: Registros exportados – Springer Link | H28: =SUMIF($C$5:$C$23,"Springer Link",$H$5:$H$23) -> 4
B29: Total de registros exportados | H29: =SUM(H26,H27,H28) -> 78
B30: Duplicados dentro de la misma base (8 Scopus fitopatológicos, 1 Scopus tecnológico, 1 ScienceDirect) | H30: 10
B31: Registros únicos por base (hoja Base_consolidada) | H31: =COUNTA(Base_consolidada!$A$4:$A$200) -> 68
B32: Comprobación: exportados − duplicados internos = únicos | H32: =IF(H29-H30=H31,"Correcto","Revisar") -> Correcto
A34: Nota metodológica: | B34: Se conservan los números originales de las cadenas (1–9, 12–15 y 16–18); los números 10 y 11 no se usaron, por lo que son 16 cadenas en total. Los totales de resultados (hits) no se registraron al buscar, por lo que el PRISMA parte de los registros exportados (limitación declarada). IEEE Xplore y Web of Science no se consultaron por falta de acceso institucional. Las cadenas 16–18 son más cortas porque ScienceDirect limita a ocho los operadores booleanos por campo (Yuan et al., 2026); los filtros de año e idioma de estas cadenas no se registraron.

Sheet Base_consolidada
A1: Base_consolidada
A2: Actividad 3 del itinerario. Registros únicos por base (78 exportados − 10 duplicados dentro de la misma base = 68), con su ID y categoría. Aún no se filtra nada: los duplicados entre bases y las revisiones se marcan en la Actividad 4 (hoja Duplicados_y_exclusion). Datos tomados de las exportaciones de Scopus (.csv), ScienceDirect y Springer Link (.ris).
A3: ID | B3: Base de datos | C3: Título completo | D3: Autores | E3: Año | F3: DOI | G3: Keywords | H3: Abstract | I3: Tipo de documento | J3: Fuente / Revista | K3: Estado inicial | L3: Registro fuente | M3: Categoría | O3: RESUMEN DE LA BASE CONSOLIDADA
A4: A0001 | B4: Scopus | C4: Avocado rhizobacteria emit volatile organic compounds with antifungal activity against Fusarium solani, Fusarium sp. associated with Kuroshio shot hole borer, and Colletotrichum gloeosporioides | D4: Guevara-Avendaño E.; Bejarano-Bolívar A.A.; Kiel-Martínez A.-L.; Ramírez-Vázquez M.; Méndez-Bravo A.; von Wobeser E.A.; Sánchez-Rangel D.; Guerrero-Analco J.A.; Eskalen A.; Reverchon F. | E4: 2019 | F4: 10.1016/j.micres.2018.11.009 | G4: Bacillus spp.; Bacterial volatiles; Biological control; Persea americana; Pseudomonas sp.; Rhizosphere; Animals; Antifungal Agents; Bacillus; Biological Control Agents; Coleoptera; Colletotrichum; Fusarium; Persea; Phytophthora; Pseudomonas; Volatile Organic Compounds; Bacillus (bacterium); Bacillus amyloliquefaciens; Bacillus mycoides; Bacteria (microorganisms); Fusarium; Fusarium solani; Fusarium sp.; Glomerella cingulata; Mycelium (genus); Persea americana; Phytophthora; Phytophthora cinnamomi; Pseudomonas; Pseudomonas sp.; Rhizobiales; Bacteria; Bacteriology; Diagnosis; Disease control; Fruits; Gas chromatography; Ketones; Mass spectrometry; Ocean currents; Soils; Sulfur compounds; Volatile organic compounds; antifungal agent; volatile organic compound; Bacillus spp; Bacterial volatiles; Biological controls; Persea americana; Pseudomonas sp; Rhizosphere; antagonism; antimicrobial activity; beetle; biological control; fruit; fungus; growth; pathogen; rhizobacterium; rhizosphere; root rot; volatile organic compound; animal; Bacillus; beetle; biological control agent; Colletotrichum; drug effect; Fusarium; metabolism; microbiology; Persea; pharmacology; Phytophthora; Pseudomonas; Fungi | H4: Recent studies showed that bacterial volatile organic compounds (VOCs) play an important role in the suppression of phytopathogens. The ability of VOCs produced by avocado (Persea americana Mill.) rhizobacteria to suppress the growth of common avocado pathogens was therefore investigated. We evaluated the antifungal activity of VOCs emitted by avocado rhizobacteria in a first screening against Fusarium solani, and in subsequent antagonism assays against Fusarium sp. associated with Kuroshio shot hole borer, Colletotrichum gloeosporioides and Phytophthora cinnamomi, responsible for Fusarium dieback, anthracnosis and Phytophthora root rot in avocado, respectively. We also analyzed the composition of the bacterial volatile profiles by solid phase microextraction (SPME) gas chromatography coupled to mass spectrometry (GC–MS). Seven isolates, belonging to the bacterial genera Bacillus and Pseudomonas, reduced the mycelial growth of F. solani with inhibition percentages higher than 20%. Isolate HA, related to Bacillus amyloliquefaciens, significantly reduced the mycelial growth of Fusarium sp. and C. gloeosporioides and the mycelium density of P. cinnamomi. Isolates SO and SJJ, also members of the genus Bacillus, reduced Fusarium sp. mycelial growth and induced morphological alterations of fungal hyphae whilst isolate HB, close to B. mycoides, inhibited C. gloeosporioides. The analysis of the volatile profiles revealed the presence of ketones, pyrazines and sulfur-containing compounds, previously reported with antifungal activity. Altogether, our results support the potential of avocado rhizobacteria to act as biocontrol agents of avocado fungal pathogens and emphasize the importance of Bacillus spp. for the control of emerging avocado diseases such as Fusarium dieback. © 2018 | I4: Article | J4: Microbiological Research | K4: Importado | L4: scopus_export_Sep 18-2026_4e658477-f683-499d-a469-81d37efaa96b.csv | M4: Fitopatológico | O4: Registros únicos por base | P4: =COUNTA($A$4:$A$71) -> 68
A5: A0002 | B5: Scopus | C5: Colletotrichum fructicola, a Member of Colletotrichum gloeosporioides sensu lato, is the causal agent of anthracnose and soft rot in avocado fruits cv. "Hass" | D5: Fuentes-Aragón D.; Juárez-Vázquez S.B.; Vargas-Hernández M.; Silva-Rojas H.V. | E5: 2018 | F5: 10.1080/12298093.2018.1454010 | G5: Bayesian inference; Colletotrichum species complex; Fungal infection; Multilocus sequencing typing; Persea americana; Phylogenetic reconstruction | H5: The filamentous Ascomycota Colletotrichum gloeosporioides sensu lato is a fungus that has been reported worldwide as a causal agent of anthracnose disease in avocado and other crops. In Mexico, this species affects fruits from an early stage of development in the orchard until the post-harvest stage. Although fungicides are continuously applied to control Colletotrichum species, pericarp cankers and soft rot mesocarp in fruits are still frequently observed. Considering the lack of a precise description of the causative agent, the aim of the current study was to determine the pathogens involved in this symptomatology. Twenty-four isolates were consistently obtained from the pericarp of avocado fruits cv. "Hass" collected in the central avocado-producing area of Mexico. Morphological features such as colony growth, conidia size, and mycelial appressorium were assessed. Bayesian multilocus phylogenetic analyses were performed using amplified sequences of the internal transcribed spacer region of the nuclear ribosomal DNA; actin, chitin synthase, glyceraldehyde-3-phosphate dehydrogenase partial genes; and APn2-Mat1-2 intergenic spacer and mating type Mat1-2 partial gene from the nine selected isolates. In addition, fruits were inoculated with a conidial suspension and reproducible symptoms confirmed the presence of Colletotrichum fructicola in this area. This pathogenic species can now be added to those previously reported in the country, such as C. acutatum, C. boninense, C. godetiae, C. gloeosporioides, and C. karstii. Disease management programs to reduce the incidence of anthracnose should include C. fructicola to determine its response to fungicides that are routinely applied, considering that the appearance of new species is affecting the commercial quality of the fruits and shifting the original population structure. © 2018 The Author(s). | I5: Article | J5: Mycobiology | K5: Importado | L5: scopus_export_Sep 18-2026_82c23d75-ee65-4935-bf31-12365c1693d4.csv | M5: Fitopatológico | O5: Scopus | P5: =COUNTIF($B$4:$B$71,"Scopus") -> 50
A6: A0003 | B6: Scopus | C6: Colletotrichum perseae and Colletotrichum gloeosporioides sensu strictu Causing Stem Lesion and Dieback in Avocado in Italy | D6: Vecchio L.; Martino I.; Guarnaccia V.; Polizzi G.; Aiello D. | E6: 2026 | F6: 10.3390/horticulturae12010111 | G6: Colletotrichum species; Persea americana; stem and fruit infections | H6: In the last decade, avocado production has increased in Italy due to the fruit’s high nutritional quality and economic value. During 2024, stem lesions, wood discoloration and dieback, often starting at the grafting point, were observed in young plants in a nursery in Sicily (Italy). Colletotrichum-like colonies were frequently isolated from symptomatic tissues. Multi-locus phylogenetic analysis (gapdh, chs-1, act, tub2, cal, gs and ApMat) was conducted on 11 representative isolates, identifying 6 as C. perseae and 5 as C. gloeosporioides sensu stricto (s.s.). Two representative isolates were selected for pathogenicity tests performed on 2-year-old avocado plants cultivated in a greenhouse. After two months, necrotic lesions, wood discoloration and reddish-brown streaking at the inoculation point were induced in both species. Additional inoculations of avocado fruit confirmed the ability of both species to cause fruit rot. All inoculated fungi were successfully re-isolated and identified, fulfilling Koch’s postulates. This is the first report of stem lesions and dieback caused by Colletotrichum species and the first occurrence of C. perseae in avocado plants in Europe. The results highlight the importance of early monitoring in nurseries during the propagation process and contribute to a better understanding of fungal diseases in avocado crops in Italy. © 2026 by the authors. | I6: Article | J6: Horticulturae | K6: Importado | L6: scopus_export_Sep 17-2026_64f2de15-f34e-4ffa-b356-5d490b5ac07b.csv | scopus_export_Sep 18-2026_82c23d75-ee65-4935-bf31-12365c1693d4.csv | M6: Fitopatológico | O6: ScienceDirect | P6: =COUNTIF($B$4:$B$71,"Science Direct") -> 14
A7: A0004 | B7: Scopus | C7: Colletotrichum siamense is the main aetiological agent of anthracnose of avocado in south-eastern Brazil | D7: Soares M.G.O.; Alves E.; Silveira A.L.; Pereira F.D.; Guimarães S.S.C. | E7: 2021 | F7: 10.1111/ppa.13262 | G7: infectious process; multilocus phylogeny; pathogenicity; Persea americana; post-harvest disease; Brazil; Colletotrichum; Colletotrichum boninense; Persea americana; anthracnose; bacterium; deciduous tree; etiology; genetic variation; inoculation; isolated population; morphology; phylogenetics; sporulation | H7: Anthracnose caused by species of Colletotrichum is considered one of the main postharvest diseases for avocado. In this study, Colletotrichum isolates associated with avocado anthracnose, collected in different states of Brazil, were evaluated through phylogenetic analysis, morphological characterization, and pathogenicity assays. Moreover, the events during pathogen infection of avocados were examined by scanning electron microscopy. To assess the genetic diversity of 54 Colletotrichum isolates, partial sequence analysis of the gene gapdh was performed. According to the generated groupings and the geographical origins of isolates, a subset of 14 strains was selected for performing multilocus phylogeny analysis (using sequences of gapdh, act, tub2, and ApMat). Two species previously described were identified: C. siamense belonging to the C. gloeosporioides species complex and Colletotrichum karstii belonging to the C. boninense species complex. All Colletotrichum strains evaluated caused typical symptoms of anthracnose in avocado fruits. Conidia of the most virulent strain germinated between 6 and 12 hr after inoculation (hai). Penetration through wounds occurred 48 hai, tissue colonization occurred between 144 and 240 hai, and sporulation took place at 240 hai via the production of an acervulus, conidiophores, and conidia. The findings shed light on the aetiology of avocado anthracnose in Brazil and provide a better understanding of the infection process of this pathogen, which may assist in the development of disease management strategies. © 2020 British Society for Plant Pathology | I7: Article | J7: Plant Pathology | K7: Importado | L7: scopus_export_Sep 17-2026_64f2de15-f34e-4ffa-b356-5d490b5ac07b.csv | M7: Fitopatológico | O7: Springer Link | P7: =COUNTIF($B$4:$B$71,"Springer Link") -> 4
A8: A0005 | B8: Scopus | C8: Colletotrichum species causing anthracnose on avocado fruit in Mexico: Current status | D8: Fuentes-Aragón D.; Silva-Rojas H.V.; Guarnaccia V.; Mora-Aguilera J.A.; Aranda-Ocampo S.; Bautista-Martínez N.; Téliz-Ortíz D. | E8: 2020 | F8: 10.1111/ppa.13234 | G8: Colletotrichum jiangxiense sexual morph; Colletotrichum species; multilocus phylogenetic analyses; pathogenicity test; Persea americana; Mexico [North America]; Colletotrichum; Colletotrichum nymphaeae; Colletotrichum sp.; Persea americana; anthracnose; bacterium; crop plant; fruit; genetic analysis; morphology; pathogenicity; phylogenetics | H8: Colletotrichum species cause anthracnose disease in tropical and subtropical fruit crops worldwide. Mexico is the main producer and exporter of avocado (Persea americana) globally and has yearly outbreaks of anthracnose on this crop. However, which specific Colletotrichum spp. cause these outbreaks in avocado-producing regions remain uncertain; thus, the objective of the present study was to identify the species responsible. A survey performed in six production regions of Mexico yielded 232 isolates, from which a subset of 104 strains was selected based on morphological characteristics and origin. This subset was sequenced and haplotypes were analysed in the gapdh partial gene. Finally, 31 strains were identified through multilocus phylogenetic analyses using the sequences of the internal transcribed spacer region and six loci. This study revealed the presence of two species previously reported in Mexico (C. karsti and C. godetiae), three novel records in Mexico (C. siamense, C. fioriniae, and C. cigarro), four novel records on avocado (C. chrysophilum, C. jiangxiense, C. tropicale, and C. nymphaeae), and two novel lineages (Colletotrichum sp. 1 and Colletotrichum sp. 2). C. siamense was the most prevalent, while the species reported for the first time on avocado, including the novel lineages, were the least prevalent. C. karsti was the most widespread (four regions), followed by C. siamense, C. jiangxiense, and C. chrysophilum (three regions). Pathogenicity tests showed that all species caused anthracnose on avocado fruit. These findings will be useful for improving the management of avocado anthracnose outbreaks in Mexico. © 2020 British Society for Plant Pathology | I8: Article | J8: Plant Pathology | K8: Importado | L8: scopus_export_Sep 17-2026_2fb2f4b0-ee23-499b-9e91-17eb9cc8aaf8.csv | M8: Fitopatológico | O8: Fitopatológicos (A0001–A0048) | P8: =COUNTIF($M$4:$M$71,"Fitopatológico") -> 48
A9: A0006 | B9: Scopus | C9: Ecofriendly management of anthracnose on avocado caused by Colletotrichum perseae in the Mediterranean basin | D9: Vecchio L.; Arrebola E.; Polizzi G.; Vitale A. | E9: 2026 | F9: 10.1002/jsf2.70088 | G9: anthracnose; avocado; Bacillus; biological control agents; sustainable agriculture; Trichoderma | H9: Background: Colletotrichum perseae, recently reported in Europe, causes stem and twig lesions and dieback, and fruit rot on avocado in several countries. Due to EU severe restrictions, there is an urgent need for sustainable alternatives to fungicides. This study aims to evaluate the preventative activity of trade bioformulates against C. perseae across detached twig, greenhouse pot-plant grown, and postharvest fruit experiments. Results: All biological treatments have significantly managed twig anthracnose infections ranging by 37%–91% reductions. Bacillus amyloliquefaciens QST713, chitosan, Trichoderma gamsii + Trichoderma asperellum mixture, and Equisetum arvense based bioformulates showed a similar efficacy of the standard fungicide (pyraclostrobin) whilst sweet orange essential oils were less effective. In potted plants grown in greenhouse, T. asperellum T34 followed by T. gamsii + T. asperellum mixture bioformulates revealed the most effective in reducing internal lesions caused by C. perseae. On the other hand, bioformulate containing B. amyloliquefaciens D747 revealed the most effective treatment in minimizing C. perseae anthracnose lesions under post-harvest conditions. Conclusion: The paper clearly showed that some trade bioformulates could represent a highly effective, environmentally friendly option for managing C. perseae of avocado. The implementation of such an approach should be imperative for developing performant strategies for other avocado diseases. This process should begin with preventive applications of Trichoderma species as T34 in nursery and preserve the health in postharvest by using B. amyloliquefaciens strains-based formulates. Indeed, the strategic adoption of these trade bioalternatives provides a concrete pathway to replace chemical fungicides. © 2026 The Author(s). JSFA Reports published by John Wiley & Sons Ltd on behalf of Society of Chemical Industry. | I9: Article | J9: JSFA reports | K9: Importado | L9: scopus_export_Sep 17-2026_64f2de15-f34e-4ffa-b356-5d490b5ac07b.csv | M9: Fitopatológico | O9: Tecnológicos (T0001–T0020) | P9: =COUNTIF($M$4:$M$71,"Tecnológico") -> 20
A10: A0007 | B10: Scopus | C10: Effect of pectin-based edible emulsion coating on changes in quality of avocado exposed to Lasiodiplodia theobromae infection | D10: Maftoonazad N.; Ramaswamy H.S.; Moalemiyan M.; Kushalappa A.C. | E10: 2007 | F10: 10.1016/j.carbpol.2006.11.020 | G10: Avocado; Coating; Color; Edible film; Lasiodiplodia theobromae; Pectin; Respiration rate; Storage; Texture; Carbohydrates; Emulsions; Food Storage; Fruits; Fungi; Persea; Botryosphaeria rhodina; Persea americana; Emulsions; Food storage; Fruits; Fungi; Edible films; Lasiodiplodia theobromae; Pectin; Respiration rate; Uncoated fruits; Carbohydrates | H10: This study was carried out to evaluate the effect of pectin-based edible emulsion coating on activity and disease severity of Lasiodiplodia theobromae in avocados, and their subsequent influence on the fruit quality. In order to assess the influence of coating and disease, avocados were sorted and devided into four equal lots and all were incubated at 20 °C for up to 4 days. The first and second lots constituted samples which were stored as coated and uncoated, respectively, without fungal inoculation. The third and fourth lots were coated and un-coated fruits inoculated with the fungal disease. For coating, a previously standardized pectin-based emulsion was used. The incubated fruits were examined for the spread of disease, respiration rate and quality parameters, color and texture. As the incubation time increased, the volume of disease (VDS) increased, which in turn influenced the respiration rate (RR) in both coated and uncoated fruits. However, the coated fruits sustained a significantly slower rate of disease spread and RR. Similarly, the associated quality changes (texture and color) were much lower in coated fruits as compared with the control. Thus, the pectin based coating was effective in controlling the spread and severity of stem end rot in avocados. Changes in physical and physiological parameters of coated and uncoated fruits were well described by some form of semi-logarithmic models and were related to the VDS as well as case dependent incubation time. © 2007. | I10: Article | J10: Carbohydrate Polymers | K10: Importado | L10: scopus_export_Sep 18-2026_8f28b456-611a-478a-9b87-bb5029e250f3.csv | M10: Fitopatológico | O10: Recuperados en dos exportaciones de la misma base | P10: =COUNTIF($L$4:$L$71,"*|*") -> 10
A11: A0008 | B11: Scopus | C11: Effect of seaweed extract on avocado root growth, yield and post-harvest quality in far north Queensland, Australia | D11: Arioli T.; Villalta O.N.; Hepworth G.; Farnsworth B.; Mattner S.W. | E11: 2024 | F11: 10.1007/s10811-023-02933-0 | G11: Ascophyllum nodosum; Biostimulant; Durvillaea potatorum; Persea americana; Phytophthora cinnamomi | H11: Seaweed extracts are proven to increase productivity in many agricultural crops, but there is limited research on their use in avocado production. Therefore, we evaluated the effectiveness of a seaweed extract from Durvillaea potatorum and Ascophyllum nodosum on avocado yield, revenue and post-harvest fruit quality in a series of field experiments in Australia, and on seedling root growth in a pot experiment. The field experiments were conducted on commercial farms across three different locations in northern Queensland over four years and utilised avocado trees with different ages, cultivars (Hass and Shepard) and inoculum pressures from Phytophthora cinnamomi. Results showed that the application of the seaweed extract by fertigation significantly improved avocado yield (kg fruit per tree) by 38%, fruit firmness by 4% (skin) and 22% (flesh) and fruit skin colour by 1° (hue), and an upgraded visual ripeness score. The increases in yield were associated with greater number of fruits per tree (up to 42%) indicating the liquid seaweed extract improved fruit set and retention per tree. Regular soil application of the seaweed extract to young trees (cv. Hass) in pots increased the root fresh weight by 22%. Overall, the regular application of the seaweed extract to avocado trees was found to be practical and economically viable for improving fruit production and post-harvest quality in Australian orchards. © The Author(s) 2023. | I11: Article | J11: Journal of Applied Phycology | K11: Importado | L11: scopus_export_Sep 18-2026_162c1d26-553e-41ee-8ea1-e9ecd3a7eea2.csv | M11: Fitopatológico
A12: A0009 | B12: Scopus | C12: Emerging pathogens and disease dynamics threatening avocado production in southern Türkiye | D12: Çalış Ö.; Çelik S.; Fidan H.; Tek M.I.; Shah M.; Tozlu I.; Wani S.H. | E12: 2024 | F12: 10.1007/s41348-024-00954-6 | G12: Anthracnose; Avocado; Branch canker; Dieback; Fungal diseases; Soil-borne pathogens; Turkey; anthracnose; biological control; dieback; fruit; fungal disease; fungus; pathogen; pathogenicity; soilborne disease | H12: Avocado (Persea americana Milll.) holds a pivotal position in global fruit crops, contributing significantly to the economies of tropical and subtropical regions. However, the rising incidence of diseases poses a substantial risk to avocado production. This comprehensive study investigated the disease landscape in Antalya, the largest avocado cultivation area in the Türkiye. A survey of 2537 avocado trees across 11 regions from 2020 to 2021 revealed alarming disease incidences, particularly in the eastern regions of Gazipasa and Alanya. Dieback, branch canker, anthracnose, and soil-borne root rot were identified as the primary diseases affecting tree canopies, twigs, and branches. Morphological and molecular analyzes unveiled a spectrum of pathogens, with Colletotrichum gloeosporioides dominating in the Mediterranean region. Notably, Phytophthora cinnamomi emerged as a severe threat, causing root rot and decline in avocado trees. Fusarium solani and Fusarium oxysporum, known for their association with tropical fruit crops, were identified in the western parts of Antalya. Additionally, we have detected Neofusicoccum parvum, Lasiodiplodia theobromae, and Neopestalotiopsis rosae in collected samples from avocado trees. The identified pathogens exhibited varying levels of severity in branch canker and anthracnose on avocado branches and leaves. Furthermore, pathogenicity evaluations shed light on the potential of these pathogens to induce severe symptoms, emphasizing the urgency for effective control measures. The exploration of cultural and biological control strategies are crucial for mitigating the impact of branch canker, dieback, and anthracnose diseases, ensuring the sustainability of avocado cultivation in the region. © The Author(s) 2024. | I12: Article | J12: Journal of Plant Diseases and Protection | K12: Importado | L12: scopus_export_Sep 17-2026_64f2de15-f34e-4ffa-b356-5d490b5ac07b.csv | scopus_export_Sep 18-2026_8f28b456-611a-478a-9b87-bb5029e250f3.csv | M12: Fitopatológico
A13: A0010 | B13: Scopus | C13: Expression of several Phytophthora cinnamomi putative RxLRs provides evidence for virulence roles in avocado | D13: Joubert M.; Backer R.; Engelbrecht J.; Van Den Berg N. | E13: 2021 | F13: 10.1371/journal.pone.0254645 | G13: Persea; Phylogeny; Phytophthora; Virulence; fungal protein; RxLR protein; unclassified drug; amino acid sequence; Article; avocado; controlled study; fungal genome; fungal virulence; gene; gene expression; gene expression profiling; nonhuman; nucleotide sequence; phylogeny; Phytophthora cinnamomi; Phytophthora root rot; root rot; RxLR gene; parasitology; pathogenicity; Persea; Phytophthora; virulence | H13: Phytophthora cinnamomi is a plant pathogenic oomycete that causes Phytophthora root rot of avocado (PRR). Currently, there is a limited understanding of the molecular interactions underlying this disease. Other Phytophthora species employ an arsenal of effector proteins to manipulate host physiology, of which the RxLR effectors contribute to virulence by interfering with host immune responses. The aim of this study was to identify candidate RxLR effectors in P. cinnamomi that play a role in establishing PRR, and to infer possible functions for these effectors. We identified 61 candidate RxLR genes which were expressed during infection of a susceptible avocado rootstock. Several of these genes were present in multiple copies in the P. cinnamomi genome, suggesting that they may contribute to pathogen fitness. Phylogenetic analysis of the manually predicted RxLR protein sequences revealed 12 P. cinnamomi RxLRs that were related to characterised effectors in other Phytophthora spp., providing clues to their functions in planta. Expression profiles of nine more RxLRs point to possible virulence roles in avocado-highlighting a way forward for studies of this interaction. This study represents the first investigation of the expression of P. cinnamomi RxLR genes during the course of avocado infection, and puts forward a pipeline to pinpoint effector genes with potential as virulence determinants, providing a foundation for the future functional characterization of RxLRs that contribute to P. cinnamomi virulence in avocado. © 2021 Joubert et al. This is an open access article distributed under the terms of the Creative Commons Attribution License, which permits unrestricted use, distribution, and reproduction in any medium, provided the original author and source are credited. | I13: Article | J13: PLoS ONE | K13: Importado | L13: scopus_export_Sep 17-2026_64f2de15-f34e-4ffa-b356-5d490b5ac07b.csv | M13: Fitopatológico
A14: A0011 | B14: Scopus | C14: First Record of Colletotrichum anthrisci Causing Anthracnose on Avocado Fruits in Chile | D14: Bustamante M.I.; Osorio-Navarro C.; Fernández Y.; Bourret T.B.; Zamorano A.; Henríquez-Sáez J.L. | E14: 2022 | F14: 10.3390/pathogens11101204 | G14: etiology; Persea americana; postharvest disease; streptomycin; anthracnose; Article; avocado; Colletotrichum; conidium; controlled study; DNA extraction; DNA sequencing; fungus isolation; mycelial growth; nonhuman; phylogeny; sporogenesis; temperature | H14: Anthracnose caused by Colletotrichum species is one of the most frequent and damaging fungal diseases affecting avocado fruits (Persea americana Mill.) worldwide. In Chile, the disease incidence has increased over the last decades due to the establishment of commercial groves in more humid areas. Since 2018, unusual symptoms of anthracnose have been observed on Hass avocado fruits, with lesions developing a white to gray sporulation. Morphological features and multi-locus phylogenetic analyses using six DNA barcodes (act, chs-1, gapdh, his3, ITS, and tub2) allowed the identification of the causal agent as Colletotrichum anthrisci, a member of the dematium species complex. Pathogenicity was confirmed by inoculating healthy Hass avocado fruits with representative isolates, reproducing the same symptoms initially observed, and successfully reisolating the same isolates from the margin of the necrotic pulp. Previously, several Colletotrichum species belonging to other species complexes have been associated with avocado anthracnose in other countries. To our knowledge, this is the first record of C. anthrisci and of a species of the dematium species complex causing anthracnose on avocado fruits in Chile and worldwide. © 2022 by the authors. | I14: Article | J14: Pathogens | K14: Importado | L14: scopus_export_Sep 17-2026_64f2de15-f34e-4ffa-b356-5d490b5ac07b.csv | M14: Fitopatológico
A15: A0012 | B15: Scopus | C15: First Report of Fusarium equiseti Causing Postharvest Fruit Rot of Avocado in Türkiye | D15: Bozoğlu T.; Derviş S.; Özer G.; Türkkan M. | E15: 2025 | F15: 10.1111/jph.70131 | G15: Fusarium equiseti; Persea americana; postharvest fruit rot; rpb2 phylogeny; stem-end rot; tef1; Black Sea; amplification; fruit; inoculation; molecular analysis; phylogeny; RNA; root rot | H15: In September 2024, postharvest fruit rot, including stem-end rot, was observed on avocado in the Altınordu district of Ordu province, located in the Eastern Black Sea Region of Türkiye. A market survey revealed that 5% of fruit exhibited fruit rot symptoms, a subset of which displayed stem-end rot symptoms, including brown to black lesions extending into the mesocarp, shrivelling and fungal mycelium growth. Fusarium equiseti was identified as the causal agent through morphological characterisation and molecular analysis using PCR amplification and sequencing of translation elongation factor 1-alpha (tef1) and RNA polymerase II second largest subunit (rpb2) gene sequences, including phylogenetic analysis. Artificial inoculation and subsequent re-isolation confirmed Koch's postulates, verifying F. equiseti as the causal pathogen. This is the first report of F. equiseti causing both fruit rot and stem-end rot on avocado in Türkiye, highlighting the need for improved postharvest disease management strategies to reduce economic losses in Türkiye's avocado industry. © 2025 The Author(s). Journal of Phytopathology published by Wiley-VCH GmbH. | I15: Article | J15: Journal of Phytopathology | K15: Importado | L15: scopus_export_Sep 17-2026_64f2de15-f34e-4ffa-b356-5d490b5ac07b.csv | scopus_export_Sep 18-2026_4e658477-f683-499d-a469-81d37efaa96b.csv | M15: Fitopatológico
A16: A0013 | B16: Scopus | C16: First report of Phytophthora cinnamomi causing avocado root rot in India | D16: Madhu G.S.; Rani A.T.; Muralidhara B.M.; Rajendiran S.; Sriram S.; Venkataravanappa V. | E16: 2023 | F16: 10.1007/s42161-023-01471-5 | G16: Avocado; Phytophthora cinnamomi; Root rot | H16: [No abstract available] | I16: Article | J16: Journal of Plant Pathology | K16: Importado | L16: scopus_export_Sep 18-2026_162c1d26-553e-41ee-8ea1-e9ecd3a7eea2.csv | M16: Fitopatológico
A17: A0014 | B17: Scopus | C17: Four new fungal pathogens causing avocado dieback in Brazil | D17: Silva T.F.; Pimentel Duarte J.L.; Vélez-Olmedo J.B.; Anderson dos Santos Vieira W.; Bassay Blum L.E.; Pinho D.B. | E17: 2025 | F17: 10.1016/j.cropro.2025.107168 | G17: Canker; Diagnosis; Persea americana; Phylogeny; Plant disease complex; Brazil; dicotyledon; dieback; etiology; fungal disease; fungus; pathogenicity; phylogeny; RNA | H17: Dieback is a disease with a complex etiology that results in the death of branches or entire plants in avocado producing regions. Losses associated with this disease have already been reported in the main producing regions of Brazil. The etiological agents of this disease are different and an association between fungi is often observed. This study aimed to identify fungi associated with avocado dieback in Brazil. Fungal isolates were collected from symptomatic avocado stems from orchards in São Paulo state. Identification was based on phenotypic characteristics and multilocus phylogenetic analysis of the translation elongation factor 1-alpha, RNA polymerase II, β-tubulin, actin, the internal transcribed spacer (ITS) region of rDNA, and the large subunit ribosomal RNA regions, according to the previously identified genus. The pathogenicity test confirmed that all species were pathogenic to avocado seedlings and fruits. This is the first report of Neopestalotiopsis arecacearum, Neocosmospora bostrycoides, Nectria pseudotrichia and Cytospora viridistroma causing avocado dieback in Brazil and worldwide. Identifying emerging pathogens that cause losses is crucial for avocado-producing countries with different climatic conditions, as it helps understand the geographic distribution of these phytopathogens and the conditions that favor their development. © 2025 Elsevier Ltd | I17: Article | J17: Crop Protection | K17: Importado | L17: scopus_export_Sep 18-2026_6573fc91-2043-414f-a3dc-1112c7ddea01.csv | M17: Fitopatológico
A18: A0015 | B18: Scopus | C18: Fungal Pathogens Associated with Aerial Symptoms of Avocado (Persea americana Mill.) in Tenerife (Canary Islands, Spain) Focused on Species of the Family Botryosphaeriaceae | D18: Hernández D.; García-Pérez O.; Perera S.; González-Carracedo M.A.; Rodríguez-Pérez A.; Siverio F. | E18: 2023 | F18: 10.3390/microorganisms11030585 | G18: canker; dieback; Lasiodiplodia brasiliensis; Neofusicoccum australe; Neofusicoccum cryptoaustrale; Neofusicoccum luteum; Neofusicoccum parvum; Neofusicoccum stellenboschiana; Persea americana; stem-end rot | H18: Fungi of the family Botryosphaeriaceae are considered responsible for various symptoms in avocado such as dieback, external necrosis of branches and inflorescences, cankers on branches and trunks, or stem-end rot of fruits. In recent years, these problems are becoming more frequent in avocado orchards in the Canary Islands (Spain). This work includes the characterization of fungal species involved in these diseases, which were isolated from avocado crops in Tenerife Island between 2018 and 2022. A total of 158 vegetal samples were collected, from which 297 fungal isolates were culture-isolated. Fifty-two of them were selected according to their morphological features as representative isolates of Botryosphaeriaceae, and their molecular characterization was carried out, sequencing the ITS1-2 region as well as the β-tubulin and the elongation factor 1-alpha genes. Five species of Botryosphaeriaceae were isolated, including Neofusicoccum australe, N. cryptoaustrale/stellenboschiana, N. luteum, N. parvum, and Lasiodiplodia brasiliensis. This is the first time that L. brasiliensis has been associated with avocado dieback and that N. cryptoaustrale/stellenboschiana has been cited in avocado causing symptoms of dieback and stem-end rot. However, it was not possible to assign our isolates unequivocally to N. cryptoaustrale or N. stellenboschiana even additionally using the rpb2 marker for their molecular characterization. Botryosphaeriaceae family seem to be involved in avocado dieback, in the premature fall of fruits during their development in the field and in post-harvest damage in Tenerife, but further studies are needed to clarify the fungal pathogens associated with symptoms in relation to phenological plant growth stages or less frequently observed. © 2023 by the authors. | I18: Article | J18: Microorganisms | K18: Importado | L18: scopus_export_Sep 18-2026_96199bb3-e2ff-4aa3-a2d7-ec2db6aced85.csv | M18: Fitopatológico
A19: A0016 | B19: Scopus | C19: Fungal Species of Botryosphaeriaceae Associated With Avocado Dieback in Southern Spain | D19: Crespo M.; Guirado-Manzano L.; Sarmiento D.; Guirado E.; de Vicente A.; Fernández-Ortuño D.; Cazorla F.M.; Arrebola E. | E19: 2026 | F19: 10.1111/ppa.70079 | G19: aetiology; cankers; Lasiodiplodia sp.; Neofusicoccum spp.; pathogenicity; Persea americana; Granada [Nicaragua]; dieback; etiology; fungal disease; fungus; irrigation system; pathogenicity; symptom | H19: Avocado (Persea americana) has become one of the most important subtropical crops in southern Spain. In recent years, the scarcity of irrigation water has made this crop susceptible to opportunistic diseases. This sensitivity has been associated with a series of symptoms characterised by the death of branches, mummification of fruits, cankers and reddening of the vascular bundles. To identify the aetiology of the disease, surveys have been carried out on avocado farms in the most affected areas, including Málaga and Granada (southern Spain). The surveys were conducted from 2019 to 2022. A total of 252 fungal isolates were recovered from trees with symptoms of dieback disease. Of these isolates, 172 were initially identified by sequencing the rDNA internal transcribed spacer (ITS) region to identify potential pathogens compatible with the symptoms. Based on the number of isolates, the most prevalent were Neofusicoccum spp. (110 isolates) and Lasiodiplodia sp. (15 isolates), although some isolates of Diaporthe sp. (four isolates) and Colletotrichum sp. (eight isolates) were also identified. Pathogenicity experiments in plants, branches and fruits confirmed these fungi as possible causal agents as they reproduced the symptoms found in diseased avocado crops. The frequency of isolates associated with dieback symptoms, along with greater severity in the reproduced symptoms, shows Botryosphaeriaceae species as the main cause of dieback in avocado in southern Spain. The main objective of the present study is to elucidate the aetiology of the disease to establish the infection time and thereby lay the groundwork for designing control studies. © 2025 The Author(s). Plant Pathology published by John Wiley & Sons Ltd on behalf of British Society for Plant Pathology. | I19: Article | J19: Plant Pathology | K19: Importado | L19: scopus_export_Sep 17-2026_64f2de15-f34e-4ffa-b356-5d490b5ac07b.csv | scopus_export_Sep 18-2026_96199bb3-e2ff-4aa3-a2d7-ec2db6aced85.csv | M19: Fitopatológico
A20: A0017 | B20: Scopus | C20: Genome assembly and annotation of Rugonectria rugulosa, a fungus associated with avocado (Persea americana cv. Hass) trunk canker in Colombia | D20: Rincón López J.D.; Chacón-Vargas K.; Clavijo-Buriticá D.C.; García-Merchán V.H. | E20: 2026 | F20: 10.1128/mra.00512-26 | G20: avocado; fungal genomics; genome assembly; Nectriaceae; plant pathogen; Rugonectria rugulosa; secondary metabolites; trunk canker; wilting; Article; avocado; Colombia; fungal genome; fungus; fungus isolation; genomics; nonhuman; phytopathogen; Rugonectria rugulosa | H20: Rugonectria rugulosa is a member of the family Nectriaceae associated with trunk canker diseases in woody plants, including avocado (Persea americana cv. Hass). Here, we report the 53 Mb draft genome assembly of a Colombian isolate, providing a genomic resource to investigate the biology and pathogenic potential of this species. Copyright © 2026 Rincón López et al. | I20: Article | J20: Microbiology Resource Announcements | K20: Importado (primer autor corregido según el PDF: Scopus lo registra como López J.D.R.) | L20: scopus_export_Sep 17-2026_64f2de15-f34e-4ffa-b356-5d490b5ac07b.csv | scopus_export_Sep 18-2026_6573fc91-2043-414f-a3dc-1112c7ddea01.csv | M20: Fitopatológico
A21: A0018 | B21: Scopus | C21: Identification and Pathogenicity of Botryosphaeriaceae, Colletotrichum, and Phytophthora Species Associated with Avocado Diseases in Italy | D21: Linaldeddu B.T.; Bregant C.; Muscas J.; Maddau L.; Vecchio L.; Polizzi G.; Aiello D. | E21: 2026 | F21: 10.3390/agriculture16101035 | G21: Botryosphaeriaceae; co-infections; holistic diagnosis; oomycetes | H21: With the rapid expansion of avocado cultivation in southern Italy, growers have had to deal with the emergence of new diseases often caused by invasive and polyphagous pathogens responsible for leaf spot, branch cankers, dieback and fruit and root rot. Given the severity of these emerging diseases, a study was conducted in the main avocado growing areas in Sardinia and Sicily (Italy) to isolate and characterize the causal agents. Specifically, a total of 430 symptomatic leaf, fruit, branch, stem and root samples were collected and examined. Isolations performed on both non-selective and selective growth media yielded 22 species (fungi and oomycetes) belonging to the genera Botryosphaeria, Colletotrichum, Diplodia, Dothiorella, Macrophomina, Neofusicoccum and Phytophthora, including 14 new host–pathogen records in Italy. Notably, Neofusicoccum australe, Phytophthora cinnamomi and Phytophthora palmivora emerged as the main pathogens involved in the emerging avocado diseases. The identified pathogens were often isolated simultaneously from the same plants, which exhibited a complex of symptoms. Pathogenicity bioassays have helped to clarify the differences in aggressiveness among the different species and their specificity towards the different plant organs. The results achieved suggest that avocado orchards’ productivity and profitability is threatened by a plethora of unrelated pathogens whose control represents a major challenge for the success of this crop in Italy. © 2026 by the authors. | I21: Article | J21: Agriculture (Switzerland) | K21: Importado | L21: scopus_export_Sep 18-2026_96199bb3-e2ff-4aa3-a2d7-ec2db6aced85.csv | M21: Fitopatológico
A22: A0019 | B22: Scopus | C22: Identification and Pathogenicity of Fungal Pathogens Associated with Stem End Rots of Avocado Fruits in Kenya | D22: Wanjiku E.K.; Waceke J.W.; Wanjala B.W.; Mbaka J.N. | E22: 2020 | F22: 10.1155/2020/4063697 | G22: No especificado | H22: Losses associated with stem end rot (SER) of avocado fruits have been reported in all avocado growing regions of the world. In Kenya, mature avocado fruits present SER symptoms during storage and marketing, but the disease causal agent(s) has not been established. This study aimed to identify the fungal pathogen(s) associated with avocado SER in Kenya and evaluate its pathogenicity. Fungal isolates were collected from symptomatic avocado fruits from randomly selected orchards and major markets within Murang'a County, a major avocado growing region in Kenya, between September 2017 and March 2018. A total of 207 and 125 fungal isolates, recovered from orchards and major markets, respectively, were identified morphologically and further confirmed by molecular techniques. The identified isolates were Lasiodiplodia theobromae (39.8%), Neofusicoccum parvum (24.4%), Nectria pseudotrichia (18.4%), Fusarium solani (7.2%), F. oxysporum (5.1%), F. equiseti (3.9%), and Geotricum candidum (1.2%). Geotricum candidum was exclusively recovered from fruits from the market. In the pathogenicity test, L. theobromae, N. parvum, and N. pseudotrichia caused the most severe SER symptoms. Consequently, they were considered to be the major pathogens of SER of avocado fruits in Kenya. To our knowledge, this is the first report of SER pathogen of avocado fruits in Kenya. Given the significant contribution of avocado fruits to household income and foreign exchange in Kenya, this information is significant to further develop management strategies of postharvest loss of avocado fruits in Kenya. © 2020 E. K. Wanjiku et al. | I22: Article | J22: International Journal of Microbiology | K22: Importado | L22: scopus_export_Sep 18-2026_6573fc91-2043-414f-a3dc-1112c7ddea01.csv | M22: Fitopatológico
